[2024-11-11T06:43:33.756+0000] {taskinstance.py:1103} INFO - Dependencies all met for dep_context=non-requeueable deps ti=<TaskInstance: kaggle_to_duckdb.download_kaggle_data manual__2024-11-11T06:43:32.192885+00:00 [queued]>
[2024-11-11T06:43:33.764+0000] {taskinstance.py:1103} INFO - Dependencies all met for dep_context=requeueable deps ti=<TaskInstance: kaggle_to_duckdb.download_kaggle_data manual__2024-11-11T06:43:32.192885+00:00 [queued]>
[2024-11-11T06:43:33.764+0000] {taskinstance.py:1308} INFO - Starting attempt 1 of 2
[2024-11-11T06:43:33.781+0000] {taskinstance.py:1327} INFO - Executing <Task(PythonOperator): download_kaggle_data> on 2024-11-11 06:43:32.192885+00:00
[2024-11-11T06:43:33.790+0000] {standard_task_runner.py:57} INFO - Started process 1219 to run task
[2024-11-11T06:43:33.795+0000] {standard_task_runner.py:84} INFO - Running: ['***', 'tasks', 'run', 'kaggle_to_duckdb', 'download_kaggle_data', 'manual__2024-11-11T06:43:32.192885+00:00', '--job-id', '25', '--raw', '--subdir', 'DAGS_FOLDER/business_etl_v1.py', '--cfg-path', '/tmp/tmp5_v0voqt']
[2024-11-11T06:43:33.801+0000] {standard_task_runner.py:85} INFO - Job 25: Subtask download_kaggle_data
[2024-11-11T06:43:33.854+0000] {task_command.py:410} INFO - Running <TaskInstance: kaggle_to_duckdb.download_kaggle_data manual__2024-11-11T06:43:32.192885+00:00 [running]> on host 2a931195ce48
[2024-11-11T06:43:33.941+0000] {taskinstance.py:1547} INFO - Exporting env vars: AIRFLOW_CTX_DAG_OWNER='***' AIRFLOW_CTX_DAG_ID='kaggle_to_duckdb' AIRFLOW_CTX_TASK_ID='download_kaggle_data' AIRFLOW_CTX_EXECUTION_DATE='2024-11-11T06:43:32.192885+00:00' AIRFLOW_CTX_TRY_NUMBER='1' AIRFLOW_CTX_DAG_RUN_ID='manual__2024-11-11T06:43:32.192885+00:00'
[2024-11-11T06:43:33.948+0000] {taskinstance.py:1824} ERROR - Task failed with exception
Traceback (most recent call last):
  File "/home/airflow/.local/lib/python3.7/site-packages/airflow/operators/python.py", line 181, in execute
    return_value = self.execute_callable()
  File "/home/airflow/.local/lib/python3.7/site-packages/airflow/operators/python.py", line 198, in execute_callable
    return self.python_callable(*self.op_args, **self.op_kwargs)
  File "/opt/airflow/dags/business_etl_v1.py", line 23, in download_kaggle_dataset
    kaggle.api.dataset_download_files(dataset, file_name, path='/data')
TypeError: dataset_download_files() got multiple values for argument 'path'
[2024-11-11T06:43:33.959+0000] {taskinstance.py:1350} INFO - Marking task as UP_FOR_RETRY. dag_id=kaggle_to_duckdb, task_id=download_kaggle_data, execution_date=20241111T064332, start_date=20241111T064333, end_date=20241111T064333
[2024-11-11T06:43:33.967+0000] {standard_task_runner.py:109} ERROR - Failed to execute job 25 for task download_kaggle_data (dataset_download_files() got multiple values for argument 'path'; 1219)
[2024-11-11T06:43:34.008+0000] {local_task_job_runner.py:225} INFO - Task exited with return code 1
[2024-11-11T06:43:34.043+0000] {taskinstance.py:2653} INFO - 0 downstream tasks scheduled from follow-on schedule check
