[2024-12-10T09:54:27.447+0000] {taskinstance.py:1103} INFO - Dependencies all met for dep_context=non-requeueable deps ti=<TaskInstance: dbt_dag_example.run_dbt manual__2024-12-10T09:54:25.533259+00:00 [queued]>
[2024-12-10T09:54:27.457+0000] {taskinstance.py:1103} INFO - Dependencies all met for dep_context=requeueable deps ti=<TaskInstance: dbt_dag_example.run_dbt manual__2024-12-10T09:54:25.533259+00:00 [queued]>
[2024-12-10T09:54:27.457+0000] {taskinstance.py:1308} INFO - Starting attempt 1 of 2
[2024-12-10T09:54:27.472+0000] {taskinstance.py:1327} INFO - Executing <Task(BashOperator): run_dbt> on 2024-12-10 09:54:25.533259+00:00
[2024-12-10T09:54:27.477+0000] {standard_task_runner.py:57} INFO - Started process 543 to run task
[2024-12-10T09:54:27.482+0000] {standard_task_runner.py:84} INFO - Running: ['***', 'tasks', 'run', 'dbt_dag_example', 'run_dbt', 'manual__2024-12-10T09:54:25.533259+00:00', '--job-id', '16', '--raw', '--subdir', 'DAGS_FOLDER/dbt_duckdb_test.py', '--cfg-path', '/tmp/tmpaz4dwwsv']
[2024-12-10T09:54:27.485+0000] {standard_task_runner.py:85} INFO - Job 16: Subtask run_dbt
[2024-12-10T09:54:27.532+0000] {task_command.py:410} INFO - Running <TaskInstance: dbt_dag_example.run_dbt manual__2024-12-10T09:54:25.533259+00:00 [running]> on host a6447c064af9
[2024-12-10T09:54:27.607+0000] {taskinstance.py:1547} INFO - Exporting env vars: AIRFLOW_CTX_DAG_OWNER='***' AIRFLOW_CTX_DAG_ID='dbt_dag_example' AIRFLOW_CTX_TASK_ID='run_dbt' AIRFLOW_CTX_EXECUTION_DATE='2024-12-10T09:54:25.533259+00:00' AIRFLOW_CTX_TRY_NUMBER='1' AIRFLOW_CTX_DAG_RUN_ID='manual__2024-12-10T09:54:25.533259+00:00'
[2024-12-10T09:54:27.608+0000] {subprocess.py:63} INFO - Tmp dir root location: /tmp
[2024-12-10T09:54:27.609+0000] {subprocess.py:75} INFO - Running command: ['/bin/bash', '-c', 'docker run --rm -v /home/***/repo:/app dbt-labs/dbt-core run --project-dir /app/my_dbt_project']
[2024-12-10T09:54:27.615+0000] {subprocess.py:86} INFO - Output:
[2024-12-10T09:54:27.635+0000] {subprocess.py:93} INFO - docker: Cannot connect to the Docker daemon at unix:///var/run/docker.sock. Is the docker daemon running?.
[2024-12-10T09:54:27.636+0000] {subprocess.py:93} INFO - See 'docker run --help'.
[2024-12-10T09:54:27.637+0000] {subprocess.py:97} INFO - Command exited with return code 125
[2024-12-10T09:54:27.647+0000] {taskinstance.py:1824} ERROR - Task failed with exception
Traceback (most recent call last):
  File "/home/airflow/.local/lib/python3.7/site-packages/airflow/operators/bash.py", line 211, in execute
    f"Bash command failed. The command returned a non-zero exit code {result.exit_code}."
airflow.exceptions.AirflowException: Bash command failed. The command returned a non-zero exit code 125.
[2024-12-10T09:54:27.651+0000] {taskinstance.py:1350} INFO - Marking task as UP_FOR_RETRY. dag_id=dbt_dag_example, task_id=run_dbt, execution_date=20241210T095425, start_date=20241210T095427, end_date=20241210T095427
[2024-12-10T09:54:27.664+0000] {standard_task_runner.py:109} ERROR - Failed to execute job 16 for task run_dbt (Bash command failed. The command returned a non-zero exit code 125.; 543)
[2024-12-10T09:54:27.696+0000] {local_task_job_runner.py:225} INFO - Task exited with return code 1
[2024-12-10T09:54:27.746+0000] {taskinstance.py:2653} INFO - 0 downstream tasks scheduled from follow-on schedule check
