[2024-11-11T06:44:43.456+0000] {taskinstance.py:1103} INFO - Dependencies all met for dep_context=non-requeueable deps ti=<TaskInstance: kaggle_to_duckdb.download_kaggle_data manual__2024-11-11T06:39:39.351730+00:00 [queued]>
[2024-11-11T06:44:43.470+0000] {taskinstance.py:1103} INFO - Dependencies all met for dep_context=requeueable deps ti=<TaskInstance: kaggle_to_duckdb.download_kaggle_data manual__2024-11-11T06:39:39.351730+00:00 [queued]>
[2024-11-11T06:44:43.471+0000] {taskinstance.py:1308} INFO - Starting attempt 2 of 2
[2024-11-11T06:44:43.485+0000] {taskinstance.py:1327} INFO - Executing <Task(PythonOperator): download_kaggle_data> on 2024-11-11 06:39:39.351730+00:00
[2024-11-11T06:44:43.494+0000] {standard_task_runner.py:57} INFO - Started process 1431 to run task
[2024-11-11T06:44:43.500+0000] {standard_task_runner.py:84} INFO - Running: ['***', 'tasks', 'run', 'kaggle_to_duckdb', 'download_kaggle_data', 'manual__2024-11-11T06:39:39.351730+00:00', '--job-id', '26', '--raw', '--subdir', 'DAGS_FOLDER/business_etl_v1.py', '--cfg-path', '/tmp/tmp_u64bm9f']
[2024-11-11T06:44:43.506+0000] {standard_task_runner.py:85} INFO - Job 26: Subtask download_kaggle_data
[2024-11-11T06:44:43.558+0000] {task_command.py:410} INFO - Running <TaskInstance: kaggle_to_duckdb.download_kaggle_data manual__2024-11-11T06:39:39.351730+00:00 [running]> on host 2a931195ce48
[2024-11-11T06:44:43.658+0000] {taskinstance.py:1547} INFO - Exporting env vars: AIRFLOW_CTX_DAG_OWNER='***' AIRFLOW_CTX_DAG_ID='kaggle_to_duckdb' AIRFLOW_CTX_TASK_ID='download_kaggle_data' AIRFLOW_CTX_EXECUTION_DATE='2024-11-11T06:39:39.351730+00:00' AIRFLOW_CTX_TRY_NUMBER='2' AIRFLOW_CTX_DAG_RUN_ID='manual__2024-11-11T06:39:39.351730+00:00'
[2024-11-11T06:44:43.665+0000] {taskinstance.py:1824} ERROR - Task failed with exception
Traceback (most recent call last):
  File "/home/airflow/.local/lib/python3.7/site-packages/airflow/operators/python.py", line 181, in execute
    return_value = self.execute_callable()
  File "/home/airflow/.local/lib/python3.7/site-packages/airflow/operators/python.py", line 198, in execute_callable
    return self.python_callable(*self.op_args, **self.op_kwargs)
  File "/opt/airflow/dags/business_etl_v1.py", line 23, in download_kaggle_dataset
    kaggle.api.dataset_download_files(dataset, file_name, path='/data')
TypeError: dataset_download_files() got multiple values for argument 'path'
[2024-11-11T06:44:43.677+0000] {taskinstance.py:1350} INFO - Marking task as FAILED. dag_id=kaggle_to_duckdb, task_id=download_kaggle_data, execution_date=20241111T063939, start_date=20241111T064443, end_date=20241111T064443
[2024-11-11T06:44:43.693+0000] {standard_task_runner.py:109} ERROR - Failed to execute job 26 for task download_kaggle_data (dataset_download_files() got multiple values for argument 'path'; 1431)
[2024-11-11T06:44:43.712+0000] {local_task_job_runner.py:225} INFO - Task exited with return code 1
[2024-11-11T06:44:43.746+0000] {taskinstance.py:2653} INFO - 0 downstream tasks scheduled from follow-on schedule check
