[2024-12-12T08:27:57.531+0000] {taskinstance.py:1103} INFO - Dependencies all met for dep_context=non-requeueable deps ti=<TaskInstance: dbt_dag_example.run_dbt manual__2024-12-12T08:27:54.914924+00:00 [queued]>
[2024-12-12T08:27:57.549+0000] {taskinstance.py:1103} INFO - Dependencies all met for dep_context=requeueable deps ti=<TaskInstance: dbt_dag_example.run_dbt manual__2024-12-12T08:27:54.914924+00:00 [queued]>
[2024-12-12T08:27:57.551+0000] {taskinstance.py:1308} INFO - Starting attempt 1 of 2
[2024-12-12T08:27:57.578+0000] {taskinstance.py:1327} INFO - Executing <Task(BashOperator): run_dbt> on 2024-12-12 08:27:54.914924+00:00
[2024-12-12T08:27:57.585+0000] {standard_task_runner.py:57} INFO - Started process 571 to run task
[2024-12-12T08:27:57.589+0000] {standard_task_runner.py:84} INFO - Running: ['***', 'tasks', 'run', 'dbt_dag_example', 'run_dbt', 'manual__2024-12-12T08:27:54.914924+00:00', '--job-id', '141', '--raw', '--subdir', 'DAGS_FOLDER/dbt_duckdb_test.py', '--cfg-path', '/tmp/tmpibbr1xey']
[2024-12-12T08:27:57.592+0000] {standard_task_runner.py:85} INFO - Job 141: Subtask run_dbt
[2024-12-12T08:27:57.661+0000] {task_command.py:410} INFO - Running <TaskInstance: dbt_dag_example.run_dbt manual__2024-12-12T08:27:54.914924+00:00 [running]> on host 9fd845b48432
[2024-12-12T08:27:57.811+0000] {taskinstance.py:1547} INFO - Exporting env vars: AIRFLOW_CTX_DAG_OWNER='***' AIRFLOW_CTX_DAG_ID='dbt_dag_example' AIRFLOW_CTX_TASK_ID='run_dbt' AIRFLOW_CTX_EXECUTION_DATE='2024-12-12T08:27:54.914924+00:00' AIRFLOW_CTX_TRY_NUMBER='1' AIRFLOW_CTX_DAG_RUN_ID='manual__2024-12-12T08:27:54.914924+00:00'
[2024-12-12T08:27:57.813+0000] {subprocess.py:63} INFO - Tmp dir root location: /tmp
[2024-12-12T08:27:57.814+0000] {subprocess.py:75} INFO - Running command: ['/bin/bash', '-c', 'docker run --rm -v /home/***/repo:/app dbt-labs/dbt-core run --project-dir /app/my_dbt_project']
[2024-12-12T08:27:57.829+0000] {subprocess.py:86} INFO - Output:
[2024-12-12T08:27:57.992+0000] {subprocess.py:93} INFO - docker: Cannot connect to the Docker daemon at unix:///var/run/docker.sock. Is the docker daemon running?.
[2024-12-12T08:27:57.994+0000] {subprocess.py:93} INFO - See 'docker run --help'.
[2024-12-12T08:27:57.995+0000] {subprocess.py:97} INFO - Command exited with return code 125
[2024-12-12T08:27:58.014+0000] {taskinstance.py:1824} ERROR - Task failed with exception
Traceback (most recent call last):
  File "/home/airflow/.local/lib/python3.7/site-packages/airflow/operators/bash.py", line 211, in execute
    f"Bash command failed. The command returned a non-zero exit code {result.exit_code}."
airflow.exceptions.AirflowException: Bash command failed. The command returned a non-zero exit code 125.
[2024-12-12T08:27:58.021+0000] {taskinstance.py:1350} INFO - Marking task as UP_FOR_RETRY. dag_id=dbt_dag_example, task_id=run_dbt, execution_date=20241212T082754, start_date=20241212T082757, end_date=20241212T082758
[2024-12-12T08:27:58.077+0000] {standard_task_runner.py:109} ERROR - Failed to execute job 141 for task run_dbt (Bash command failed. The command returned a non-zero exit code 125.; 571)
[2024-12-12T08:27:58.125+0000] {local_task_job_runner.py:225} INFO - Task exited with return code 1
[2024-12-12T08:27:58.166+0000] {taskinstance.py:2653} INFO - 0 downstream tasks scheduled from follow-on schedule check
