[2024-12-04T09:58:26.673+0000] {taskinstance.py:1103} INFO - Dependencies all met for dep_context=non-requeueable deps ti=<TaskInstance: process_weather_data.load_weather_data_to_duckdb manual__2024-12-04T09:58:25.218065+00:00 [queued]>
[2024-12-04T09:58:26.680+0000] {taskinstance.py:1103} INFO - Dependencies all met for dep_context=requeueable deps ti=<TaskInstance: process_weather_data.load_weather_data_to_duckdb manual__2024-12-04T09:58:25.218065+00:00 [queued]>
[2024-12-04T09:58:26.680+0000] {taskinstance.py:1308} INFO - Starting attempt 1 of 2
[2024-12-04T09:58:26.692+0000] {taskinstance.py:1327} INFO - Executing <Task(PythonOperator): load_weather_data_to_duckdb> on 2024-12-04 09:58:25.218065+00:00
[2024-12-04T09:58:26.699+0000] {standard_task_runner.py:57} INFO - Started process 420 to run task
[2024-12-04T09:58:26.701+0000] {standard_task_runner.py:84} INFO - Running: ['***', 'tasks', 'run', 'process_weather_data', 'load_weather_data_to_duckdb', 'manual__2024-12-04T09:58:25.218065+00:00', '--job-id', '123', '--raw', '--subdir', 'DAGS_FOLDER/weather_to_duckdb.py', '--cfg-path', '/tmp/tmpxdmjwkxt']
[2024-12-04T09:58:26.704+0000] {standard_task_runner.py:85} INFO - Job 123: Subtask load_weather_data_to_duckdb
[2024-12-04T09:58:26.746+0000] {task_command.py:410} INFO - Running <TaskInstance: process_weather_data.load_weather_data_to_duckdb manual__2024-12-04T09:58:25.218065+00:00 [running]> on host f858c1e8e12d
[2024-12-04T09:58:26.812+0000] {taskinstance.py:1547} INFO - Exporting env vars: AIRFLOW_CTX_DAG_OWNER='***' AIRFLOW_CTX_DAG_ID='process_weather_data' AIRFLOW_CTX_TASK_ID='load_weather_data_to_duckdb' AIRFLOW_CTX_EXECUTION_DATE='2024-12-04T09:58:25.218065+00:00' AIRFLOW_CTX_TRY_NUMBER='1' AIRFLOW_CTX_DAG_RUN_ID='manual__2024-12-04T09:58:25.218065+00:00'
[2024-12-04T09:58:26.875+0000] {taskinstance.py:1824} ERROR - Task failed with exception
Traceback (most recent call last):
  File "/home/airflow/.local/lib/python3.7/site-packages/airflow/operators/python.py", line 181, in execute
    return_value = self.execute_callable()
  File "/home/airflow/.local/lib/python3.7/site-packages/airflow/operators/python.py", line 198, in execute_callable
    return self.python_callable(*self.op_args, **self.op_kwargs)
  File "/opt/airflow/dags/weather_to_duckdb.py", line 68, in load_weather_data_to_duckdb
    """, aggregated_df.values.tolist())
duckdb.duckdb.InvalidInputException: Invalid Input Error: Prepared statement needs 4 parameters, 3 given
[2024-12-04T09:58:26.888+0000] {taskinstance.py:1350} INFO - Marking task as UP_FOR_RETRY. dag_id=process_weather_data, task_id=load_weather_data_to_duckdb, execution_date=20241204T095825, start_date=20241204T095826, end_date=20241204T095826
[2024-12-04T09:58:26.900+0000] {standard_task_runner.py:109} ERROR - Failed to execute job 123 for task load_weather_data_to_duckdb (Invalid Input Error: Prepared statement needs 4 parameters, 3 given; 420)
[2024-12-04T09:58:26.915+0000] {local_task_job_runner.py:225} INFO - Task exited with return code 1
[2024-12-04T09:58:26.931+0000] {taskinstance.py:2653} INFO - 0 downstream tasks scheduled from follow-on schedule check
