[2024-12-10T12:46:03.422+0000] {taskinstance.py:1103} INFO - Dependencies all met for dep_context=non-requeueable deps ti=<TaskInstance: fortune_500_data_processing.read_data_from_duckdb manual__2024-12-10T12:46:01.452694+00:00 [queued]>
[2024-12-10T12:46:03.435+0000] {taskinstance.py:1103} INFO - Dependencies all met for dep_context=requeueable deps ti=<TaskInstance: fortune_500_data_processing.read_data_from_duckdb manual__2024-12-10T12:46:01.452694+00:00 [queued]>
[2024-12-10T12:46:03.435+0000] {taskinstance.py:1308} INFO - Starting attempt 1 of 2
[2024-12-10T12:46:03.454+0000] {taskinstance.py:1327} INFO - Executing <Task(PythonOperator): read_data_from_duckdb> on 2024-12-10 12:46:01.452694+00:00
[2024-12-10T12:46:03.461+0000] {standard_task_runner.py:57} INFO - Started process 1417 to run task
[2024-12-10T12:46:03.465+0000] {standard_task_runner.py:84} INFO - Running: ['***', 'tasks', 'run', 'fortune_500_data_processing', 'read_data_from_duckdb', 'manual__2024-12-10T12:46:01.452694+00:00', '--job-id', '22', '--raw', '--subdir', 'DAGS_FOLDER/business_transform.py', '--cfg-path', '/tmp/tmpvgo60g11']
[2024-12-10T12:46:03.467+0000] {standard_task_runner.py:85} INFO - Job 22: Subtask read_data_from_duckdb
[2024-12-10T12:46:03.526+0000] {task_command.py:410} INFO - Running <TaskInstance: fortune_500_data_processing.read_data_from_duckdb manual__2024-12-10T12:46:01.452694+00:00 [running]> on host 521a110c9dc3
[2024-12-10T12:46:03.610+0000] {taskinstance.py:1547} INFO - Exporting env vars: AIRFLOW_CTX_DAG_OWNER='***' AIRFLOW_CTX_DAG_ID='fortune_500_data_processing' AIRFLOW_CTX_TASK_ID='read_data_from_duckdb' AIRFLOW_CTX_EXECUTION_DATE='2024-12-10T12:46:01.452694+00:00' AIRFLOW_CTX_TRY_NUMBER='1' AIRFLOW_CTX_DAG_RUN_ID='manual__2024-12-10T12:46:01.452694+00:00'
[2024-12-10T12:46:03.635+0000] {taskinstance.py:1824} ERROR - Task failed with exception
Traceback (most recent call last):
  File "/home/airflow/.local/lib/python3.7/site-packages/airflow/operators/python.py", line 181, in execute
    return_value = self.execute_callable()
  File "/home/airflow/.local/lib/python3.7/site-packages/airflow/operators/python.py", line 198, in execute_callable
    return self.python_callable(*self.op_args, **self.op_kwargs)
  File "/opt/airflow/dags/business_transform.py", line 11, in read_data_from_duckdb
    conn = duckdb.connect(database=db_path, read_only=False)
duckdb.duckdb.IOException: IO Error: Cannot open file "/opt/***/./repo/data/my_duckdb_file.db": No such file or directory
[2024-12-10T12:46:03.646+0000] {taskinstance.py:1350} INFO - Marking task as UP_FOR_RETRY. dag_id=fortune_500_data_processing, task_id=read_data_from_duckdb, execution_date=20241210T124601, start_date=20241210T124603, end_date=20241210T124603
[2024-12-10T12:46:03.659+0000] {standard_task_runner.py:109} ERROR - Failed to execute job 22 for task read_data_from_duckdb (IO Error: Cannot open file "/opt/***/./repo/data/my_duckdb_file.db": No such file or directory; 1417)
[2024-12-10T12:46:03.678+0000] {local_task_job_runner.py:225} INFO - Task exited with return code 1
[2024-12-10T12:46:03.701+0000] {taskinstance.py:2653} INFO - 0 downstream tasks scheduled from follow-on schedule check
