[2024-12-12T08:44:17.108+0000] {taskinstance.py:1103} INFO - Dependencies all met for dep_context=non-requeueable deps ti=<TaskInstance: dbt_dag_example.run_dbt manual__2024-12-12T08:39:12.344634+00:00 [queued]>
[2024-12-12T08:44:17.125+0000] {taskinstance.py:1103} INFO - Dependencies all met for dep_context=requeueable deps ti=<TaskInstance: dbt_dag_example.run_dbt manual__2024-12-12T08:39:12.344634+00:00 [queued]>
[2024-12-12T08:44:17.126+0000] {taskinstance.py:1308} INFO - Starting attempt 2 of 2
[2024-12-12T08:44:17.153+0000] {taskinstance.py:1327} INFO - Executing <Task(BashOperator): run_dbt> on 2024-12-12 08:39:12.344634+00:00
[2024-12-12T08:44:17.162+0000] {standard_task_runner.py:57} INFO - Started process 1775 to run task
[2024-12-12T08:44:17.165+0000] {standard_task_runner.py:84} INFO - Running: ['***', 'tasks', 'run', 'dbt_dag_example', 'run_dbt', 'manual__2024-12-12T08:39:12.344634+00:00', '--job-id', '152', '--raw', '--subdir', 'DAGS_FOLDER/dbt_duckdb_test.py', '--cfg-path', '/tmp/tmpcde3at76']
[2024-12-12T08:44:17.170+0000] {standard_task_runner.py:85} INFO - Job 152: Subtask run_dbt
[2024-12-12T08:44:17.248+0000] {task_command.py:410} INFO - Running <TaskInstance: dbt_dag_example.run_dbt manual__2024-12-12T08:39:12.344634+00:00 [running]> on host 58ec26063232
[2024-12-12T08:44:17.365+0000] {taskinstance.py:1547} INFO - Exporting env vars: AIRFLOW_CTX_DAG_OWNER='***' AIRFLOW_CTX_DAG_ID='dbt_dag_example' AIRFLOW_CTX_TASK_ID='run_dbt' AIRFLOW_CTX_EXECUTION_DATE='2024-12-12T08:39:12.344634+00:00' AIRFLOW_CTX_TRY_NUMBER='2' AIRFLOW_CTX_DAG_RUN_ID='manual__2024-12-12T08:39:12.344634+00:00'
[2024-12-12T08:44:17.367+0000] {subprocess.py:63} INFO - Tmp dir root location: /tmp
[2024-12-12T08:44:17.369+0000] {subprocess.py:75} INFO - Running command: ['/bin/bash', '-c', 'docker exec -i dbt dbt run --models business_transformed']
[2024-12-12T08:44:17.379+0000] {subprocess.py:86} INFO - Output:
[2024-12-12T08:44:17.421+0000] {subprocess.py:93} INFO - Cannot connect to the Docker daemon at unix:///var/run/docker.sock. Is the docker daemon running?
[2024-12-12T08:44:17.423+0000] {subprocess.py:97} INFO - Command exited with return code 1
[2024-12-12T08:44:17.438+0000] {taskinstance.py:1824} ERROR - Task failed with exception
Traceback (most recent call last):
  File "/home/airflow/.local/lib/python3.7/site-packages/airflow/operators/bash.py", line 211, in execute
    f"Bash command failed. The command returned a non-zero exit code {result.exit_code}."
airflow.exceptions.AirflowException: Bash command failed. The command returned a non-zero exit code 1.
[2024-12-12T08:44:17.444+0000] {taskinstance.py:1350} INFO - Marking task as FAILED. dag_id=dbt_dag_example, task_id=run_dbt, execution_date=20241212T083912, start_date=20241212T084417, end_date=20241212T084417
[2024-12-12T08:44:17.463+0000] {standard_task_runner.py:109} ERROR - Failed to execute job 152 for task run_dbt (Bash command failed. The command returned a non-zero exit code 1.; 1775)
[2024-12-12T08:44:17.503+0000] {local_task_job_runner.py:225} INFO - Task exited with return code 1
[2024-12-12T08:44:17.564+0000] {taskinstance.py:2653} INFO - 0 downstream tasks scheduled from follow-on schedule check
