[2024-12-12T08:39:15.830+0000] {taskinstance.py:1103} INFO - Dependencies all met for dep_context=non-requeueable deps ti=<TaskInstance: dbt_dag_example.run_dbt manual__2024-12-12T08:39:12.344634+00:00 [queued]>
[2024-12-12T08:39:15.839+0000] {taskinstance.py:1103} INFO - Dependencies all met for dep_context=requeueable deps ti=<TaskInstance: dbt_dag_example.run_dbt manual__2024-12-12T08:39:12.344634+00:00 [queued]>
[2024-12-12T08:39:15.840+0000] {taskinstance.py:1308} INFO - Starting attempt 1 of 2
[2024-12-12T08:39:15.852+0000] {taskinstance.py:1327} INFO - Executing <Task(BashOperator): run_dbt> on 2024-12-12 08:39:12.344634+00:00
[2024-12-12T08:39:15.859+0000] {standard_task_runner.py:57} INFO - Started process 721 to run task
[2024-12-12T08:39:15.861+0000] {standard_task_runner.py:84} INFO - Running: ['***', 'tasks', 'run', 'dbt_dag_example', 'run_dbt', 'manual__2024-12-12T08:39:12.344634+00:00', '--job-id', '147', '--raw', '--subdir', 'DAGS_FOLDER/dbt_duckdb_test.py', '--cfg-path', '/tmp/tmpaa2w93gp']
[2024-12-12T08:39:15.863+0000] {standard_task_runner.py:85} INFO - Job 147: Subtask run_dbt
[2024-12-12T08:39:15.908+0000] {task_command.py:410} INFO - Running <TaskInstance: dbt_dag_example.run_dbt manual__2024-12-12T08:39:12.344634+00:00 [running]> on host 5d84e668b1bf
[2024-12-12T08:39:15.983+0000] {taskinstance.py:1547} INFO - Exporting env vars: AIRFLOW_CTX_DAG_OWNER='***' AIRFLOW_CTX_DAG_ID='dbt_dag_example' AIRFLOW_CTX_TASK_ID='run_dbt' AIRFLOW_CTX_EXECUTION_DATE='2024-12-12T08:39:12.344634+00:00' AIRFLOW_CTX_TRY_NUMBER='1' AIRFLOW_CTX_DAG_RUN_ID='manual__2024-12-12T08:39:12.344634+00:00'
[2024-12-12T08:39:15.984+0000] {subprocess.py:63} INFO - Tmp dir root location: /tmp
[2024-12-12T08:39:15.985+0000] {subprocess.py:75} INFO - Running command: ['/bin/bash', '-c', 'docker exec -i dbt dbt run --models business_transformed']
[2024-12-12T08:39:15.994+0000] {subprocess.py:86} INFO - Output:
[2024-12-12T08:39:16.015+0000] {subprocess.py:93} INFO - Cannot connect to the Docker daemon at unix:///var/run/docker.sock. Is the docker daemon running?
[2024-12-12T08:39:16.017+0000] {subprocess.py:97} INFO - Command exited with return code 1
[2024-12-12T08:39:16.027+0000] {taskinstance.py:1824} ERROR - Task failed with exception
Traceback (most recent call last):
  File "/home/airflow/.local/lib/python3.7/site-packages/airflow/operators/bash.py", line 211, in execute
    f"Bash command failed. The command returned a non-zero exit code {result.exit_code}."
airflow.exceptions.AirflowException: Bash command failed. The command returned a non-zero exit code 1.
[2024-12-12T08:39:16.030+0000] {taskinstance.py:1350} INFO - Marking task as UP_FOR_RETRY. dag_id=dbt_dag_example, task_id=run_dbt, execution_date=20241212T083912, start_date=20241212T083915, end_date=20241212T083916
[2024-12-12T08:39:16.042+0000] {standard_task_runner.py:109} ERROR - Failed to execute job 147 for task run_dbt (Bash command failed. The command returned a non-zero exit code 1.; 721)
[2024-12-12T08:39:16.075+0000] {local_task_job_runner.py:225} INFO - Task exited with return code 1
[2024-12-12T08:39:16.096+0000] {taskinstance.py:2653} INFO - 0 downstream tasks scheduled from follow-on schedule check
