[2024-12-04T08:23:27.199+0000] {taskinstance.py:1103} INFO - Dependencies all met for dep_context=non-requeueable deps ti=<TaskInstance: verify_duckdb.validate_duckdb manual__2024-12-04T08:23:26.166527+00:00 [queued]>
[2024-12-04T08:23:27.208+0000] {taskinstance.py:1103} INFO - Dependencies all met for dep_context=requeueable deps ti=<TaskInstance: verify_duckdb.validate_duckdb manual__2024-12-04T08:23:26.166527+00:00 [queued]>
[2024-12-04T08:23:27.208+0000] {taskinstance.py:1308} INFO - Starting attempt 1 of 2
[2024-12-04T08:23:27.221+0000] {taskinstance.py:1327} INFO - Executing <Task(PythonOperator): validate_duckdb> on 2024-12-04 08:23:26.166527+00:00
[2024-12-04T08:23:27.226+0000] {standard_task_runner.py:57} INFO - Started process 438 to run task
[2024-12-04T08:23:27.229+0000] {standard_task_runner.py:84} INFO - Running: ['***', 'tasks', 'run', 'verify_duckdb', 'validate_duckdb', 'manual__2024-12-04T08:23:26.166527+00:00', '--job-id', '88', '--raw', '--subdir', 'DAGS_FOLDER/verify_duckdb.py', '--cfg-path', '/tmp/tmpqmnk6mjx']
[2024-12-04T08:23:27.231+0000] {standard_task_runner.py:85} INFO - Job 88: Subtask validate_duckdb
[2024-12-04T08:23:27.281+0000] {task_command.py:410} INFO - Running <TaskInstance: verify_duckdb.validate_duckdb manual__2024-12-04T08:23:26.166527+00:00 [running]> on host aa4ec98ec0ed
[2024-12-04T08:23:27.360+0000] {taskinstance.py:1547} INFO - Exporting env vars: AIRFLOW_CTX_DAG_OWNER='***' AIRFLOW_CTX_DAG_ID='verify_duckdb' AIRFLOW_CTX_TASK_ID='validate_duckdb' AIRFLOW_CTX_EXECUTION_DATE='2024-12-04T08:23:26.166527+00:00' AIRFLOW_CTX_TRY_NUMBER='1' AIRFLOW_CTX_DAG_RUN_ID='manual__2024-12-04T08:23:26.166527+00:00'
[2024-12-04T08:23:27.361+0000] {taskinstance.py:1824} ERROR - Task failed with exception
Traceback (most recent call last):
  File "/home/airflow/.local/lib/python3.7/site-packages/airflow/operators/python.py", line 181, in execute
    return_value = self.execute_callable()
  File "/home/airflow/.local/lib/python3.7/site-packages/airflow/operators/python.py", line 198, in execute_callable
    return self.python_callable(*self.op_args, **self.op_kwargs)
  File "/opt/airflow/dags/verify_duckdb.py", line 20, in check_duckdb_file
    raise FileNotFoundError(f"DuckDB file not found at {db_path}")
FileNotFoundError: DuckDB file not found at ./data/my_duckdb_file.db
[2024-12-04T08:23:27.373+0000] {taskinstance.py:1350} INFO - Marking task as UP_FOR_RETRY. dag_id=verify_duckdb, task_id=validate_duckdb, execution_date=20241204T082326, start_date=20241204T082327, end_date=20241204T082327
[2024-12-04T08:23:27.384+0000] {standard_task_runner.py:109} ERROR - Failed to execute job 88 for task validate_duckdb (DuckDB file not found at ./data/my_duckdb_file.db; 438)
[2024-12-04T08:23:27.401+0000] {local_task_job_runner.py:225} INFO - Task exited with return code 1
[2024-12-04T08:23:27.417+0000] {taskinstance.py:2653} INFO - 0 downstream tasks scheduled from follow-on schedule check
