[2024-12-10T13:18:09.533+0000] {taskinstance.py:1103} INFO - Dependencies all met for dep_context=non-requeueable deps ti=<TaskInstance: weather_data_processing.load_data_to_duckdb manual__2024-12-10T13:18:03.296739+00:00 [queued]>
[2024-12-10T13:18:09.547+0000] {taskinstance.py:1103} INFO - Dependencies all met for dep_context=requeueable deps ti=<TaskInstance: weather_data_processing.load_data_to_duckdb manual__2024-12-10T13:18:03.296739+00:00 [queued]>
[2024-12-10T13:18:09.547+0000] {taskinstance.py:1308} INFO - Starting attempt 1 of 2
[2024-12-10T13:18:09.568+0000] {taskinstance.py:1327} INFO - Executing <Task(PythonOperator): load_data_to_duckdb> on 2024-12-10 13:18:03.296739+00:00
[2024-12-10T13:18:09.579+0000] {standard_task_runner.py:57} INFO - Started process 9799 to run task
[2024-12-10T13:18:09.597+0000] {standard_task_runner.py:84} INFO - Running: ['***', 'tasks', 'run', 'weather_data_processing', 'load_data_to_duckdb', 'manual__2024-12-10T13:18:03.296739+00:00', '--job-id', '37', '--raw', '--subdir', 'DAGS_FOLDER/weather_transform.py', '--cfg-path', '/tmp/tmpihklibwg']
[2024-12-10T13:18:09.611+0000] {standard_task_runner.py:85} INFO - Job 37: Subtask load_data_to_duckdb
[2024-12-10T13:18:09.793+0000] {task_command.py:410} INFO - Running <TaskInstance: weather_data_processing.load_data_to_duckdb manual__2024-12-10T13:18:03.296739+00:00 [running]> on host 134bb3434cfb
[2024-12-10T13:18:09.917+0000] {taskinstance.py:1547} INFO - Exporting env vars: AIRFLOW_CTX_DAG_OWNER='***' AIRFLOW_CTX_DAG_ID='weather_data_processing' AIRFLOW_CTX_TASK_ID='load_data_to_duckdb' AIRFLOW_CTX_EXECUTION_DATE='2024-12-10T13:18:03.296739+00:00' AIRFLOW_CTX_TRY_NUMBER='1' AIRFLOW_CTX_DAG_RUN_ID='manual__2024-12-10T13:18:03.296739+00:00'
[2024-12-10T13:18:09.958+0000] {taskinstance.py:1824} ERROR - Task failed with exception
Traceback (most recent call last):
  File "/home/airflow/.local/lib/python3.7/site-packages/airflow/operators/python.py", line 181, in execute
    return_value = self.execute_callable()
  File "/home/airflow/.local/lib/python3.7/site-packages/airflow/operators/python.py", line 198, in execute_callable
    return self.python_callable(*self.op_args, **self.op_kwargs)
  File "/opt/airflow/dags/weather_transform.py", line 36, in load_data_to_duckdb
    for table_name, df in tables.items():
AttributeError: 'NoneType' object has no attribute 'items'
[2024-12-10T13:18:09.970+0000] {taskinstance.py:1350} INFO - Marking task as UP_FOR_RETRY. dag_id=weather_data_processing, task_id=load_data_to_duckdb, execution_date=20241210T131803, start_date=20241210T131809, end_date=20241210T131809
[2024-12-10T13:18:09.985+0000] {standard_task_runner.py:109} ERROR - Failed to execute job 37 for task load_data_to_duckdb ('NoneType' object has no attribute 'items'; 9799)
[2024-12-10T13:18:10.013+0000] {local_task_job_runner.py:225} INFO - Task exited with return code 1
[2024-12-10T13:18:10.031+0000] {taskinstance.py:2653} INFO - 0 downstream tasks scheduled from follow-on schedule check
