[2024-12-10T13:16:04.978+0000] {taskinstance.py:1103} INFO - Dependencies all met for dep_context=non-requeueable deps ti=<TaskInstance: fortune_500_data_processing.read_data_from_duckdb manual__2024-12-10T13:16:03.439836+00:00 [queued]>
[2024-12-10T13:16:04.990+0000] {taskinstance.py:1103} INFO - Dependencies all met for dep_context=requeueable deps ti=<TaskInstance: fortune_500_data_processing.read_data_from_duckdb manual__2024-12-10T13:16:03.439836+00:00 [queued]>
[2024-12-10T13:16:04.991+0000] {taskinstance.py:1308} INFO - Starting attempt 1 of 2
[2024-12-10T13:16:05.013+0000] {taskinstance.py:1327} INFO - Executing <Task(PythonOperator): read_data_from_duckdb> on 2024-12-10 13:16:03.439836+00:00
[2024-12-10T13:16:05.020+0000] {standard_task_runner.py:57} INFO - Started process 8890 to run task
[2024-12-10T13:16:05.024+0000] {standard_task_runner.py:84} INFO - Running: ['***', 'tasks', 'run', 'fortune_500_data_processing', 'read_data_from_duckdb', 'manual__2024-12-10T13:16:03.439836+00:00', '--job-id', '34', '--raw', '--subdir', 'DAGS_FOLDER/business_transform.py', '--cfg-path', '/tmp/tmpcs07yt9i']
[2024-12-10T13:16:05.027+0000] {standard_task_runner.py:85} INFO - Job 34: Subtask read_data_from_duckdb
[2024-12-10T13:16:05.081+0000] {task_command.py:410} INFO - Running <TaskInstance: fortune_500_data_processing.read_data_from_duckdb manual__2024-12-10T13:16:03.439836+00:00 [running]> on host 134bb3434cfb
[2024-12-10T13:16:05.251+0000] {taskinstance.py:1547} INFO - Exporting env vars: AIRFLOW_CTX_DAG_OWNER='***' AIRFLOW_CTX_DAG_ID='fortune_500_data_processing' AIRFLOW_CTX_TASK_ID='read_data_from_duckdb' AIRFLOW_CTX_EXECUTION_DATE='2024-12-10T13:16:03.439836+00:00' AIRFLOW_CTX_TRY_NUMBER='1' AIRFLOW_CTX_DAG_RUN_ID='manual__2024-12-10T13:16:03.439836+00:00'
[2024-12-10T13:16:05.255+0000] {taskinstance.py:1824} ERROR - Task failed with exception
Traceback (most recent call last):
  File "/home/airflow/.local/lib/python3.7/site-packages/airflow/operators/python.py", line 181, in execute
    return_value = self.execute_callable()
  File "/home/airflow/.local/lib/python3.7/site-packages/airflow/operators/python.py", line 198, in execute_callable
    return self.python_callable(*self.op_args, **self.op_kwargs)
  File "/opt/airflow/dags/business_transform.py", line 11, in read_data_from_duckdb
    conn = duckdb.connect(database=db_path, read_only=False)
duckdb.duckdb.IOException: IO Error: Cannot open file "/opt/***/./data/my_duckdb_file.db": Permission denied
[2024-12-10T13:16:05.267+0000] {taskinstance.py:1350} INFO - Marking task as UP_FOR_RETRY. dag_id=fortune_500_data_processing, task_id=read_data_from_duckdb, execution_date=20241210T131603, start_date=20241210T131604, end_date=20241210T131605
[2024-12-10T13:16:05.280+0000] {standard_task_runner.py:109} ERROR - Failed to execute job 34 for task read_data_from_duckdb (IO Error: Cannot open file "/opt/***/./data/my_duckdb_file.db": Permission denied; 8890)
[2024-12-10T13:16:05.317+0000] {local_task_job_runner.py:225} INFO - Task exited with return code 1
[2024-12-10T13:16:05.341+0000] {taskinstance.py:2653} INFO - 0 downstream tasks scheduled from follow-on schedule check
