[2024-11-11T06:14:46.555+0000] {taskinstance.py:1103} INFO - Dependencies all met for dep_context=non-requeueable deps ti=<TaskInstance: kaggle_to_duckdb.download_kaggle_data manual__2024-11-11T06:14:43.855777+00:00 [queued]>
[2024-11-11T06:14:46.567+0000] {taskinstance.py:1103} INFO - Dependencies all met for dep_context=requeueable deps ti=<TaskInstance: kaggle_to_duckdb.download_kaggle_data manual__2024-11-11T06:14:43.855777+00:00 [queued]>
[2024-11-11T06:14:46.568+0000] {taskinstance.py:1308} INFO - Starting attempt 1 of 2
[2024-11-11T06:14:46.595+0000] {taskinstance.py:1327} INFO - Executing <Task(PythonOperator): download_kaggle_data> on 2024-11-11 06:14:43.855777+00:00
[2024-11-11T06:14:46.607+0000] {standard_task_runner.py:57} INFO - Started process 451 to run task
[2024-11-11T06:14:46.614+0000] {standard_task_runner.py:84} INFO - Running: ['***', 'tasks', 'run', 'kaggle_to_duckdb', 'download_kaggle_data', 'manual__2024-11-11T06:14:43.855777+00:00', '--job-id', '14', '--raw', '--subdir', 'DAGS_FOLDER/business_etl_v1.py', '--cfg-path', '/tmp/tmp4b1x6akm']
[2024-11-11T06:14:46.618+0000] {standard_task_runner.py:85} INFO - Job 14: Subtask download_kaggle_data
[2024-11-11T06:14:46.688+0000] {task_command.py:410} INFO - Running <TaskInstance: kaggle_to_duckdb.download_kaggle_data manual__2024-11-11T06:14:43.855777+00:00 [running]> on host bf27d4848f4c
[2024-11-11T06:14:46.809+0000] {taskinstance.py:1547} INFO - Exporting env vars: AIRFLOW_CTX_DAG_OWNER='***' AIRFLOW_CTX_DAG_ID='kaggle_to_duckdb' AIRFLOW_CTX_TASK_ID='download_kaggle_data' AIRFLOW_CTX_EXECUTION_DATE='2024-11-11T06:14:43.855777+00:00' AIRFLOW_CTX_TRY_NUMBER='1' AIRFLOW_CTX_DAG_RUN_ID='manual__2024-11-11T06:14:43.855777+00:00'
[2024-11-11T06:14:46.819+0000] {taskinstance.py:1824} ERROR - Task failed with exception
Traceback (most recent call last):
  File "/home/airflow/.local/lib/python3.7/site-packages/airflow/operators/python.py", line 181, in execute
    return_value = self.execute_callable()
  File "/home/airflow/.local/lib/python3.7/site-packages/airflow/operators/python.py", line 198, in execute_callable
    return self.python_callable(*self.op_args, **self.op_kwargs)
  File "/opt/airflow/dags/business_etl_v1.py", line 23, in download_kaggle_dataset
    kaggle.api.dataset_download_file(dataset, file_name, path='/data')
  File "/home/airflow/.local/lib/python3.7/site-packages/kaggle/api/kaggle_api_extended.py", line 1437, in dataset_download_file
    self.validate_dataset_string(dataset)
  File "/home/airflow/.local/lib/python3.7/site-packages/kaggle/api/kaggle_api_extended.py", line 4153, in validate_dataset_string
    raise ValueError('Invalid dataset specification ' + dataset)
ValueError: Invalid dataset specification https://www.kaggle.com/datasets/mannmann2/fortune-500-corporate-headquarters
[2024-11-11T06:14:46.832+0000] {taskinstance.py:1350} INFO - Marking task as UP_FOR_RETRY. dag_id=kaggle_to_duckdb, task_id=download_kaggle_data, execution_date=20241111T061443, start_date=20241111T061446, end_date=20241111T061446
[2024-11-11T06:14:46.847+0000] {standard_task_runner.py:109} ERROR - Failed to execute job 14 for task download_kaggle_data (Invalid dataset specification https://www.kaggle.com/datasets/mannmann2/fortune-500-corporate-headquarters; 451)
[2024-11-11T06:14:46.866+0000] {local_task_job_runner.py:225} INFO - Task exited with return code 1
[2024-11-11T06:14:46.901+0000] {taskinstance.py:2653} INFO - 0 downstream tasks scheduled from follow-on schedule check
