[2024-12-04T08:24:11.415+0000] {taskinstance.py:1103} INFO - Dependencies all met for dep_context=non-requeueable deps ti=<TaskInstance: verify_duckdb.validate_duckdb manual__2024-12-04T08:24:10.594720+00:00 [queued]>
[2024-12-04T08:24:11.421+0000] {taskinstance.py:1103} INFO - Dependencies all met for dep_context=requeueable deps ti=<TaskInstance: verify_duckdb.validate_duckdb manual__2024-12-04T08:24:10.594720+00:00 [queued]>
[2024-12-04T08:24:11.422+0000] {taskinstance.py:1308} INFO - Starting attempt 1 of 2
[2024-12-04T08:24:11.434+0000] {taskinstance.py:1327} INFO - Executing <Task(PythonOperator): validate_duckdb> on 2024-12-04 08:24:10.594720+00:00
[2024-12-04T08:24:11.439+0000] {standard_task_runner.py:57} INFO - Started process 677 to run task
[2024-12-04T08:24:11.442+0000] {standard_task_runner.py:84} INFO - Running: ['***', 'tasks', 'run', 'verify_duckdb', 'validate_duckdb', 'manual__2024-12-04T08:24:10.594720+00:00', '--job-id', '91', '--raw', '--subdir', 'DAGS_FOLDER/verify_duckdb.py', '--cfg-path', '/tmp/tmpoyr4sqze']
[2024-12-04T08:24:11.444+0000] {standard_task_runner.py:85} INFO - Job 91: Subtask validate_duckdb
[2024-12-04T08:24:11.483+0000] {task_command.py:410} INFO - Running <TaskInstance: verify_duckdb.validate_duckdb manual__2024-12-04T08:24:10.594720+00:00 [running]> on host aa4ec98ec0ed
[2024-12-04T08:24:11.547+0000] {taskinstance.py:1547} INFO - Exporting env vars: AIRFLOW_CTX_DAG_OWNER='***' AIRFLOW_CTX_DAG_ID='verify_duckdb' AIRFLOW_CTX_TASK_ID='validate_duckdb' AIRFLOW_CTX_EXECUTION_DATE='2024-12-04T08:24:10.594720+00:00' AIRFLOW_CTX_TRY_NUMBER='1' AIRFLOW_CTX_DAG_RUN_ID='manual__2024-12-04T08:24:10.594720+00:00'
[2024-12-04T08:24:11.586+0000] {taskinstance.py:1824} ERROR - Task failed with exception
Traceback (most recent call last):
  File "/opt/airflow/dags/verify_duckdb.py", line 27, in check_duckdb_file
    result = conn.execute(f"SELECT * FROM {table_name} LIMIT 5").fetchdf()
duckdb.duckdb.CatalogException: Catalog Error: Table with name business does not exist!
Did you mean "duckdb_indexes"?
LINE 1: SELECT * FROM business LIMIT 5
                      ^

During handling of the above exception, another exception occurred:

Traceback (most recent call last):
  File "/home/airflow/.local/lib/python3.7/site-packages/airflow/operators/python.py", line 181, in execute
    return_value = self.execute_callable()
  File "/home/airflow/.local/lib/python3.7/site-packages/airflow/operators/python.py", line 198, in execute_callable
    return self.python_callable(*self.op_args, **self.op_kwargs)
  File "/opt/airflow/dags/verify_duckdb.py", line 34, in check_duckdb_file
    raise ValueError(f"Error accessing table {table_name}: {e}")
ValueError: Error accessing table business: Catalog Error: Table with name business does not exist!
Did you mean "duckdb_indexes"?
LINE 1: SELECT * FROM business LIMIT 5
                      ^
[2024-12-04T08:24:11.598+0000] {taskinstance.py:1350} INFO - Marking task as UP_FOR_RETRY. dag_id=verify_duckdb, task_id=validate_duckdb, execution_date=20241204T082410, start_date=20241204T082411, end_date=20241204T082411
[2024-12-04T08:24:11.609+0000] {standard_task_runner.py:109} ERROR - Failed to execute job 91 for task validate_duckdb (Error accessing table business: Catalog Error: Table with name business does not exist!
Did you mean "duckdb_indexes"?
LINE 1: SELECT * FROM business LIMIT 5
                      ^; 677)
[2024-12-04T08:24:11.655+0000] {local_task_job_runner.py:225} INFO - Task exited with return code 1
[2024-12-04T08:24:11.670+0000] {taskinstance.py:2653} INFO - 0 downstream tasks scheduled from follow-on schedule check
