[2024-12-04T08:44:59.546+0000] {taskinstance.py:1103} INFO - Dependencies all met for dep_context=non-requeueable deps ti=<TaskInstance: kaggle_to_duckdb.load_data_to_duckdb manual__2024-12-04T08:44:55.874899+00:00 [queued]>
[2024-12-04T08:44:59.563+0000] {taskinstance.py:1103} INFO - Dependencies all met for dep_context=requeueable deps ti=<TaskInstance: kaggle_to_duckdb.load_data_to_duckdb manual__2024-12-04T08:44:55.874899+00:00 [queued]>
[2024-12-04T08:44:59.564+0000] {taskinstance.py:1308} INFO - Starting attempt 1 of 2
[2024-12-04T08:44:59.590+0000] {taskinstance.py:1327} INFO - Executing <Task(PythonOperator): load_data_to_duckdb> on 2024-12-04 08:44:55.874899+00:00
[2024-12-04T08:44:59.603+0000] {standard_task_runner.py:57} INFO - Started process 2416 to run task
[2024-12-04T08:44:59.607+0000] {standard_task_runner.py:84} INFO - Running: ['***', 'tasks', 'run', 'kaggle_to_duckdb', 'load_data_to_duckdb', 'manual__2024-12-04T08:44:55.874899+00:00', '--job-id', '103', '--raw', '--subdir', 'DAGS_FOLDER/business_etl_v1.py', '--cfg-path', '/tmp/tmpggrl8c_h']
[2024-12-04T08:44:59.609+0000] {standard_task_runner.py:85} INFO - Job 103: Subtask load_data_to_duckdb
[2024-12-04T08:44:59.667+0000] {task_command.py:410} INFO - Running <TaskInstance: kaggle_to_duckdb.load_data_to_duckdb manual__2024-12-04T08:44:55.874899+00:00 [running]> on host e919c4bb8fbe
[2024-12-04T08:44:59.801+0000] {taskinstance.py:1547} INFO - Exporting env vars: AIRFLOW_CTX_DAG_OWNER='***' AIRFLOW_CTX_DAG_ID='kaggle_to_duckdb' AIRFLOW_CTX_TASK_ID='load_data_to_duckdb' AIRFLOW_CTX_EXECUTION_DATE='2024-12-04T08:44:55.874899+00:00' AIRFLOW_CTX_TRY_NUMBER='1' AIRFLOW_CTX_DAG_RUN_ID='manual__2024-12-04T08:44:55.874899+00:00'
[2024-12-04T08:44:59.804+0000] {taskinstance.py:1824} ERROR - Task failed with exception
Traceback (most recent call last):
  File "/home/airflow/.local/lib/python3.7/site-packages/airflow/operators/python.py", line 181, in execute
    return_value = self.execute_callable()
  File "/home/airflow/.local/lib/python3.7/site-packages/airflow/operators/python.py", line 198, in execute_callable
    return self.python_callable(*self.op_args, **self.op_kwargs)
  File "/opt/airflow/dags/business_etl_v1.py", line 50, in load_to_duckdb
    raise FileNotFoundError(f"File {file_name} not found in ./data")
FileNotFoundError: File Fortune_500.csv not found in ./data
[2024-12-04T08:44:59.820+0000] {taskinstance.py:1350} INFO - Marking task as UP_FOR_RETRY. dag_id=kaggle_to_duckdb, task_id=load_data_to_duckdb, execution_date=20241204T084455, start_date=20241204T084459, end_date=20241204T084459
[2024-12-04T08:44:59.837+0000] {standard_task_runner.py:109} ERROR - Failed to execute job 103 for task load_data_to_duckdb (File Fortune_500.csv not found in ./data; 2416)
[2024-12-04T08:44:59.861+0000] {local_task_job_runner.py:225} INFO - Task exited with return code 1
[2024-12-04T08:44:59.905+0000] {taskinstance.py:2653} INFO - 0 downstream tasks scheduled from follow-on schedule check
